Exception in thread Thread-20 (train_models_background):
Traceback (most recent call last):
  File "/root/AI/venv/lib/python3.10/site-packages/streamlit/runtime/state/session_state.py", line 398, in __getitem__
    return self._getitem(widget_id, key)
  File "/root/AI/venv/lib/python3.10/site-packages/streamlit/runtime/state/session_state.py", line 443, in _getitem
    raise KeyError
KeyError

During handling of the above exception, another exception occurred:

Traceback (most recent call last):
  File "/root/AI/venv/lib/python3.10/site-packages/streamlit/runtime/state/session_state_proxy.py", line 119, in __getattr__
    return self[key]
  File "/root/AI/venv/lib/python3.10/site-packages/streamlit/runtime/state/session_state_proxy.py", line 90, in __getitem__
    return get_session_state()[key]
  File "/root/AI/venv/lib/python3.10/site-packages/streamlit/runtime/state/safe_session_state.py", line 91, in __getitem__
    return self._state[key]
  File "/root/AI/venv/lib/python3.10/site-packages/streamlit/runtime/state/session_state.py", line 400, in __getitem__
    raise KeyError(_missing_key_error_message(key))
KeyError: 'st.session_state has no key "training_log_messages". Did you forget to initialize it? More info: https://docs.streamlit.io/library/advanced-features/session-state#initialization'

During handling of the above exception, another exception occurred:

Traceback (most recent call last):
  File "/root/AI/AITradingOracle/app.py", line 635, in train_models_background
    update_log("Bắt đầu quá trình huấn luyện mô hình AI trong nền...")
  File "/root/AI/AITradingOracle/app.py", line 799, in update_log
    st.session_state.training_log_messages.append(log_msg)
  File "/root/AI/venv/lib/python3.10/site-packages/streamlit/runtime/state/session_state_proxy.py", line 121, in __getattr__
    raise AttributeError(_missing_attr_error_message(key))
AttributeError: st.session_state has no attribute "training_log_messages". Did you forget to initialize it? More info: https://docs.streamlit.io/library/advanced-features/session-state#initialization

During handling of the above exception, another exception occurred:

Traceback (most recent call last):
  File "/root/AI/venv/lib/python3.10/site-packages/streamlit/runtime/state/session_state.py", line 398, in __getitem__
    return self._getitem(widget_id, key)
  File "/root/AI/venv/lib/python3.10/site-packages/streamlit/runtime/state/session_state.py", line 443, in _getitem
    raise KeyError
KeyError

During handling of the above exception, another exception occurred:

Traceback (most recent call last):
  File "/root/AI/venv/lib/python3.10/site-packages/streamlit/runtime/state/session_state_proxy.py", line 119, in __getattr__
    return self[key]
  File "/root/AI/venv/lib/python3.10/site-packages/streamlit/runtime/state/session_state_proxy.py", line 90, in __getitem__
    return get_session_state()[key]
  File "/root/AI/venv/lib/python3.10/site-packages/streamlit/runtime/state/safe_session_state.py", line 91, in __getitem__
    return self._state[key]
  File "/root/AI/venv/lib/python3.10/site-packages/streamlit/runtime/state/session_state.py", line 400, in __getitem__
    raise KeyError(_missing_key_error_message(key))
KeyError: 'st.session_state has no key "training_log_messages". Did you forget to initialize it? More info: https://docs.streamlit.io/library/advanced-features/session-state#initialization'

During handling of the above exception, another exception occurred:

Traceback (most recent call last):
  File "/usr/lib/python3.10/threading.py", line 1016, in _bootstrap_inner
    self.run()
  File "/usr/lib/python3.10/threading.py", line 953, in run
    self._target(*self._args, **self._kwargs)
  File "/root/AI/AITradingOracle/app.py", line 753, in train_models_background
    update_log(f"LỖI trong quá trình huấn luyện: {str(e)}")
  File "/root/AI/AITradingOracle/app.py", line 799, in update_log
    st.session_state.training_log_messages.append(log_msg)
  File "/root/AI/venv/lib/python3.10/site-packages/streamlit/runtime/state/session_state_proxy.py", line 121, in __getattr__
/root/AI/venv/lib/python3.10/site-packages/numpy/core/fromnumeric.py:3432: RuntimeWarning:

Mean of empty slice.

/root/AI/venv/lib/python3.10/site-packages/numpy/core/_methods.py:190: RuntimeWarning:

invalid value encountered in double_scalars

    raise AttributeError(_missing_attr_error_message(key))
AttributeError: st.session_state has no attribute "training_log_messages". Did you forget to initialize it? More info: https://docs.streamlit.io/library/advanced-features/session-state#initialization
